<mujoco model="base">
  <compiler angle="radian" meshdir="meshes/"/>

  <option impratio="20" density="1.2" viscosity="2e-05" cone="elliptic"/>

  <size njmax="5000" nconmax="5000"/>

  <visual>
    <global offwidth="1280" offheight="800"/>
    <map znear="0.001"/>
  </visual>

  <asset>
    <texture type="skybox" builtin="gradient" rgb1="0.9 0.9 1" rgb2="0.2 0.3 0.4" width="256" height="1536"/>
    <texture type="2d" name="texplane" file="/home/frank/miniconda3/envs/frl/lib/python3.10/site-packages/robosuite/models/assets/arenas/../textures/light-gray-floor-tile.png"/>
    <texture type="2d" name="tex-light-gray-plaster" file="/home/frank/miniconda3/envs/frl/lib/python3.10/site-packages/robosuite/models/assets/arenas/../textures/light-gray-plaster.png"/>
    <material name="floorplane" texture="texplane" texuniform="true" texrepeat="2 2" specular="0" shininess="0" reflectance="0.01"/>
    <material name="walls_mat" texture="tex-light-gray-plaster" texuniform="true" texrepeat="3 3" specular="0.1" shininess="0.1"/>
    <material name="robot0_Black" shininess="0.25" rgba="0.033102 0.033102 0.033102 1"/>
    <material name="robot0_JointGrey" shininess="0.25" rgba="0.278431 0.278431 0.278431 1"/>
    <material name="robot0_LinkGrey" shininess="0.25" rgba="0.820392 0.820392 0.820392 1"/>
    <material name="robot0_URBlue" shininess="0.25" rgba="0.490196 0.678431 0.8 1"/>
    <mesh name="robot0_base_vis_0" file="/home/frank/miniconda3/envs/frl/lib/python3.10/site-packages/robosuite/models/assets/robots/ur5e/obj_meshes/base_vis/base_vis_0.obj"/>
    <mesh name="robot0_base_vis_1" file="/home/frank/miniconda3/envs/frl/lib/python3.10/site-packages/robosuite/models/assets/robots/ur5e/obj_meshes/base_vis/base_vis_1.obj"/>
    <mesh name="robot0_forearm_vis_0" file="/home/frank/miniconda3/envs/frl/lib/python3.10/site-packages/robosuite/models/assets/robots/ur5e/obj_meshes/forearm_vis/forearm_vis_0.obj"/>
    <mesh name="robot0_forearm_vis_1" file="/home/frank/miniconda3/envs/frl/lib/python3.10/site-packages/robosuite/models/assets/robots/ur5e/obj_meshes/forearm_vis/forearm_vis_1.obj"/>
    <mesh name="robot0_forearm_vis_2" file="/home/frank/miniconda3/envs/frl/lib/python3.10/site-packages/robosuite/models/assets/robots/ur5e/obj_meshes/forearm_vis/forearm_vis_2.obj"/>
    <mesh name="robot0_forearm_vis_3" file="/home/frank/miniconda3/envs/frl/lib/python3.10/site-packages/robosuite/models/assets/robots/ur5e/obj_meshes/forearm_vis/forearm_vis_3.obj"/>
    <mesh name="robot0_shoulder_vis_0" file="/home/frank/miniconda3/envs/frl/lib/python3.10/site-packages/robosuite/models/assets/robots/ur5e/obj_meshes/shoulder_vis/shoulder_vis_0.obj"/>
    <mesh name="robot0_shoulder_vis_1" file="/home/frank/miniconda3/envs/frl/lib/python3.10/site-packages/robosuite/models/assets/robots/ur5e/obj_meshes/shoulder_vis/shoulder_vis_1.obj"/>
    <mesh name="robot0_shoulder_vis_2" file="/home/frank/miniconda3/envs/frl/lib/python3.10/site-packages/robosuite/models/assets/robots/ur5e/obj_meshes/shoulder_vis/shoulder_vis_2.obj"/>
    <mesh name="robot0_upperarm_vis_0" file="/home/frank/miniconda3/envs/frl/lib/python3.10/site-packages/robosuite/models/assets/robots/ur5e/obj_meshes/upperarm_vis/upperarm_vis_0.obj"/>
    <mesh name="robot0_upperarm_vis_1" file="/home/frank/miniconda3/envs/frl/lib/python3.10/site-packages/robosuite/models/assets/robots/ur5e/obj_meshes/upperarm_vis/upperarm_vis_1.obj"/>
    <mesh name="robot0_upperarm_vis_2" file="/home/frank/miniconda3/envs/frl/lib/python3.10/site-packages/robosuite/models/assets/robots/ur5e/obj_meshes/upperarm_vis/upperarm_vis_2.obj"/>
    <mesh name="robot0_upperarm_vis_3" file="/home/frank/miniconda3/envs/frl/lib/python3.10/site-packages/robosuite/models/assets/robots/ur5e/obj_meshes/upperarm_vis/upperarm_vis_3.obj"/>
    <mesh name="robot0_wrist1_vis_0" file="/home/frank/miniconda3/envs/frl/lib/python3.10/site-packages/robosuite/models/assets/robots/ur5e/obj_meshes/wrist1_vis/wrist1_vis_0.obj"/>
    <mesh name="robot0_wrist1_vis_1" file="/home/frank/miniconda3/envs/frl/lib/python3.10/site-packages/robosuite/models/assets/robots/ur5e/obj_meshes/wrist1_vis/wrist1_vis_1.obj"/>
    <mesh name="robot0_wrist1_vis_2" file="/home/frank/miniconda3/envs/frl/lib/python3.10/site-packages/robosuite/models/assets/robots/ur5e/obj_meshes/wrist1_vis/wrist1_vis_2.obj"/>
    <mesh name="robot0_wrist2_vis_0" file="/home/frank/miniconda3/envs/frl/lib/python3.10/site-packages/robosuite/models/assets/robots/ur5e/obj_meshes/wrist2_vis/wrist2_vis_0.obj"/>
    <mesh name="robot0_wrist2_vis_1" file="/home/frank/miniconda3/envs/frl/lib/python3.10/site-packages/robosuite/models/assets/robots/ur5e/obj_meshes/wrist2_vis/wrist2_vis_1.obj"/>
    <mesh name="robot0_wrist2_vis_2" file="/home/frank/miniconda3/envs/frl/lib/python3.10/site-packages/robosuite/models/assets/robots/ur5e/obj_meshes/wrist2_vis/wrist2_vis_2.obj"/>
    <mesh name="robot0_wrist3_vis" file="/home/frank/miniconda3/envs/frl/lib/python3.10/site-packages/robosuite/models/assets/robots/ur5e/obj_meshes/wrist3_vis/wrist3_vis.obj"/>
    <mesh name="robot0_base" file="/home/frank/miniconda3/envs/frl/lib/python3.10/site-packages/robosuite/models/assets/robots/ur5e/meshes/base.stl"/>
    <mesh name="robot0_shoulder" file="/home/frank/miniconda3/envs/frl/lib/python3.10/site-packages/robosuite/models/assets/robots/ur5e/meshes/shoulder.stl"/>
    <mesh name="robot0_upperarm" file="/home/frank/miniconda3/envs/frl/lib/python3.10/site-packages/robosuite/models/assets/robots/ur5e/meshes/upperarm.stl"/>
    <mesh name="robot0_forearm" file="/home/frank/miniconda3/envs/frl/lib/python3.10/site-packages/robosuite/models/assets/robots/ur5e/meshes/forearm.stl"/>
    <mesh name="robot0_wrist1" file="/home/frank/miniconda3/envs/frl/lib/python3.10/site-packages/robosuite/models/assets/robots/ur5e/meshes/wrist1.stl"/>
    <mesh name="robot0_wrist2" file="/home/frank/miniconda3/envs/frl/lib/python3.10/site-packages/robosuite/models/assets/robots/ur5e/meshes/wrist2.stl"/>
    <mesh name="robot0_wrist3" file="/home/frank/miniconda3/envs/frl/lib/python3.10/site-packages/robosuite/models/assets/robots/ur5e/meshes/wrist3.stl"/>
    <mesh name="mount0_pedestal" file="/home/frank/miniconda3/envs/frl/lib/python3.10/site-packages/robosuite/models/assets/mounts/meshes/rethink_mount/pedestal.stl"/>
    <mesh name="gripper0_robotiq_arg2f_base_link" file="/home/frank/miniconda3/envs/frl/lib/python3.10/site-packages/robosuite/models/assets/grippers/meshes/robotiq_85_gripper/robotiq_arg2f_base_link.stl"/>
    <mesh name="gripper0_robotiq_arg2f_85_outer_knuckle" file="/home/frank/miniconda3/envs/frl/lib/python3.10/site-packages/robosuite/models/assets/grippers/meshes/robotiq_85_gripper/robotiq_arg2f_85_outer_knuckle.stl" scale="0.001 0.001 0.001"/>
    <mesh name="gripper0_robotiq_arg2f_85_outer_finger" file="/home/frank/miniconda3/envs/frl/lib/python3.10/site-packages/robosuite/models/assets/grippers/meshes/robotiq_85_gripper/robotiq_arg2f_85_outer_finger.stl" scale="0.001 0.001 0.001"/>
    <mesh name="gripper0_robotiq_arg2f_85_inner_finger" file="/home/frank/miniconda3/envs/frl/lib/python3.10/site-packages/robosuite/models/assets/grippers/meshes/robotiq_85_gripper/robotiq_arg2f_85_inner_finger.stl" scale="0.001 0.001 0.001"/>
    <mesh name="gripper0_robotiq_arg2f_85_inner_knuckle" file="/home/frank/miniconda3/envs/frl/lib/python3.10/site-packages/robosuite/models/assets/grippers/meshes/robotiq_85_gripper/robotiq_arg2f_85_inner_knuckle.stl" scale="0.001 0.001 0.001"/>
    <mesh name="gripper0_robotiq_arg2f_85_outer_knuckle_vis" file="/home/frank/miniconda3/envs/frl/lib/python3.10/site-packages/robosuite/models/assets/grippers/meshes/robotiq_85_gripper/robotiq_arg2f_85_outer_knuckle_vis.stl" scale="0.001 0.001 0.001"/>
    <mesh name="gripper0_robotiq_arg2f_85_outer_finger_vis" file="/home/frank/miniconda3/envs/frl/lib/python3.10/site-packages/robosuite/models/assets/grippers/meshes/robotiq_85_gripper/robotiq_arg2f_85_outer_finger_vis.stl" scale="0.001 0.001 0.001"/>
    <mesh name="gripper0_robotiq_arg2f_85_inner_finger_vis" file="/home/frank/miniconda3/envs/frl/lib/python3.10/site-packages/robosuite/models/assets/grippers/meshes/robotiq_85_gripper/robotiq_arg2f_85_inner_finger_vis.stl" scale="0.001 0.001 0.001"/>
    <mesh name="gripper0_robotiq_arg2f_85_inner_knuckle_vis" file="/home/frank/miniconda3/envs/frl/lib/python3.10/site-packages/robosuite/models/assets/grippers/meshes/robotiq_85_gripper/robotiq_arg2f_85_inner_knuckle_vis.stl" scale="0.001 0.001 0.001"/>
    <mesh name="train-microwave-1_new-6" file="/home/frank/frl/ForceRL/sim_models/train-microwave-1/new-6.stl" scale="0.3 0.3 0.3"/>
    <mesh name="train-microwave-1_new-5" file="/home/frank/frl/ForceRL/sim_models/train-microwave-1/new-5.stl" scale="0.3 0.3 0.3"/>
    <mesh name="train-microwave-1_original-3" file="/home/frank/frl/ForceRL/sim_models/train-microwave-1/original-3.stl" scale="0.3 0.3 0.3"/>
    <mesh name="train-microwave-1_original-4" file="/home/frank/frl/ForceRL/sim_models/train-microwave-1/original-4.stl" scale="0.3 0.3 0.3"/>
    <mesh name="train-microwave-1_original-41" file="/home/frank/frl/ForceRL/sim_models/train-microwave-1/original-41.stl" scale="0.3 0.3 0.3"/>
    <mesh name="train-microwave-1_original-36" file="/home/frank/frl/ForceRL/sim_models/train-microwave-1/original-36.stl" scale="0.3 0.3 0.3"/>
    <mesh name="train-microwave-1_original-35" file="/home/frank/frl/ForceRL/sim_models/train-microwave-1/original-35.stl" scale="0.3 0.3 0.3"/>
    <mesh name="train-microwave-1_original-19" file="/home/frank/frl/ForceRL/sim_models/train-microwave-1/original-19.stl" scale="0.3 0.3 0.3"/>
    <mesh name="train-microwave-1_original-42" file="/home/frank/frl/ForceRL/sim_models/train-microwave-1/original-42.stl" scale="0.3 0.3 0.3"/>
    <mesh name="train-microwave-1_original-34" file="/home/frank/frl/ForceRL/sim_models/train-microwave-1/original-34.stl" scale="0.3 0.3 0.3"/>
    <mesh name="train-microwave-1_original-31" file="/home/frank/frl/ForceRL/sim_models/train-microwave-1/original-31.stl" scale="0.3 0.3 0.3"/>
    <mesh name="train-microwave-1_original-18" file="/home/frank/frl/ForceRL/sim_models/train-microwave-1/original-18.stl" scale="0.3 0.3 0.3"/>
    <mesh name="train-microwave-1_original-17" file="/home/frank/frl/ForceRL/sim_models/train-microwave-1/original-17.stl" scale="0.3 0.3 0.3"/>
    <mesh name="train-microwave-1_original-33" file="/home/frank/frl/ForceRL/sim_models/train-microwave-1/original-33.stl" scale="0.3 0.3 0.3"/>
    <mesh name="train-microwave-1_original-32" file="/home/frank/frl/ForceRL/sim_models/train-microwave-1/original-32.stl" scale="0.3 0.3 0.3"/>
    <mesh name="train-microwave-1_original-16" file="/home/frank/frl/ForceRL/sim_models/train-microwave-1/original-16.stl" scale="0.3 0.3 0.3"/>
    <mesh name="train-microwave-1_original-15" file="/home/frank/frl/ForceRL/sim_models/train-microwave-1/original-15.stl" scale="0.3 0.3 0.3"/>
    <mesh name="train-microwave-1_original-30" file="/home/frank/frl/ForceRL/sim_models/train-microwave-1/original-30.stl" scale="0.3 0.3 0.3"/>
    <mesh name="train-microwave-1_original-14" file="/home/frank/frl/ForceRL/sim_models/train-microwave-1/original-14.stl" scale="0.3 0.3 0.3"/>
    <mesh name="train-microwave-1_original-29" file="/home/frank/frl/ForceRL/sim_models/train-microwave-1/original-29.stl" scale="0.3 0.3 0.3"/>
    <mesh name="train-microwave-1_original-40" file="/home/frank/frl/ForceRL/sim_models/train-microwave-1/original-40.stl" scale="0.3 0.3 0.3"/>
    <mesh name="train-microwave-1_original-13" file="/home/frank/frl/ForceRL/sim_models/train-microwave-1/original-13.stl" scale="0.3 0.3 0.3"/>
    <mesh name="train-microwave-1_original-39" file="/home/frank/frl/ForceRL/sim_models/train-microwave-1/original-39.stl" scale="0.3 0.3 0.3"/>
    <mesh name="train-microwave-1_original-22" file="/home/frank/frl/ForceRL/sim_models/train-microwave-1/original-22.stl" scale="0.3 0.3 0.3"/>
    <mesh name="train-microwave-1_original-20" file="/home/frank/frl/ForceRL/sim_models/train-microwave-1/original-20.stl" scale="0.3 0.3 0.3"/>
    <mesh name="train-microwave-1_original-38" file="/home/frank/frl/ForceRL/sim_models/train-microwave-1/original-38.stl" scale="0.3 0.3 0.3"/>
    <mesh name="train-microwave-1_original-23" file="/home/frank/frl/ForceRL/sim_models/train-microwave-1/original-23.stl" scale="0.3 0.3 0.3"/>
    <mesh name="train-microwave-1_original-37" file="/home/frank/frl/ForceRL/sim_models/train-microwave-1/original-37.stl" scale="0.3 0.3 0.3"/>
    <mesh name="train-microwave-1_original-48" file="/home/frank/frl/ForceRL/sim_models/train-microwave-1/original-48.stl" scale="0.3 0.3 0.3"/>
    <mesh name="train-microwave-1_original-21" file="/home/frank/frl/ForceRL/sim_models/train-microwave-1/original-21.stl" scale="0.3 0.3 0.3"/>
    <mesh name="train-microwave-1_original-46" file="/home/frank/frl/ForceRL/sim_models/train-microwave-1/original-46.stl" scale="0.3 0.3 0.3"/>
    <mesh name="train-microwave-1_original-27" file="/home/frank/frl/ForceRL/sim_models/train-microwave-1/original-27.stl" scale="0.3 0.3 0.3"/>
    <mesh name="train-microwave-1_original-28" file="/home/frank/frl/ForceRL/sim_models/train-microwave-1/original-28.stl" scale="0.3 0.3 0.3"/>
    <mesh name="train-microwave-1_original-45" file="/home/frank/frl/ForceRL/sim_models/train-microwave-1/original-45.stl" scale="0.3 0.3 0.3"/>
    <mesh name="train-microwave-1_original-47" file="/home/frank/frl/ForceRL/sim_models/train-microwave-1/original-47.stl" scale="0.3 0.3 0.3"/>
    <mesh name="train-microwave-1_original-25" file="/home/frank/frl/ForceRL/sim_models/train-microwave-1/original-25.stl" scale="0.3 0.3 0.3"/>
    <mesh name="train-microwave-1_original-44" file="/home/frank/frl/ForceRL/sim_models/train-microwave-1/original-44.stl" scale="0.3 0.3 0.3"/>
    <mesh name="train-microwave-1_original-24" file="/home/frank/frl/ForceRL/sim_models/train-microwave-1/original-24.stl" scale="0.3 0.3 0.3"/>
    <mesh name="train-microwave-1_original-43" file="/home/frank/frl/ForceRL/sim_models/train-microwave-1/original-43.stl" scale="0.3 0.3 0.3"/>
    <mesh name="train-microwave-1_original-26" file="/home/frank/frl/ForceRL/sim_models/train-microwave-1/original-26.stl" scale="0.3 0.3 0.3"/>
    <mesh name="train-microwave-1_original-10" file="/home/frank/frl/ForceRL/sim_models/train-microwave-1/original-10.stl" scale="0.3 0.3 0.3"/>
    <mesh name="train-microwave-1_original-12" file="/home/frank/frl/ForceRL/sim_models/train-microwave-1/original-12.stl" scale="0.3 0.3 0.3"/>
    <mesh name="train-microwave-1_new-4" file="/home/frank/frl/ForceRL/sim_models/train-microwave-1/new-4.stl" scale="0.3 0.3 0.3"/>
    <mesh name="train-microwave-1_original-49" file="/home/frank/frl/ForceRL/sim_models/train-microwave-1/original-49.stl" scale="0.3 0.3 0.3"/>
    <mesh name="train-microwave-1_original-51" file="/home/frank/frl/ForceRL/sim_models/train-microwave-1/original-51.stl" scale="0.3 0.3 0.3"/>
    <mesh name="train-microwave-1_original-1" file="/home/frank/frl/ForceRL/sim_models/train-microwave-1/original-1.stl" scale="0.3 0.3 0.3"/>
    <mesh name="train-microwave-1_original-50" file="/home/frank/frl/ForceRL/sim_models/train-microwave-1/original-50.stl" scale="0.3 0.3 0.3"/>
    <mesh name="train-microwave-1_new-3" file="/home/frank/frl/ForceRL/sim_models/train-microwave-1/new-3.stl" scale="0.3 0.3 0.3"/>
    <mesh name="train-microwave-1_new-2" file="/home/frank/frl/ForceRL/sim_models/train-microwave-1/new-2.stl" scale="0.3 0.3 0.3"/>
    <mesh name="train-microwave-1_new-1" file="/home/frank/frl/ForceRL/sim_models/train-microwave-1/new-1.stl" scale="0.3 0.3 0.3"/>
    <mesh name="train-microwave-1_new-0" file="/home/frank/frl/ForceRL/sim_models/train-microwave-1/new-0.stl" scale="0.3 0.3 0.3"/>
  </asset>

  <worldbody>
    <geom name="floor" size="3 3 0.125" type="plane" group="1" material="floorplane"/>
    <geom name="wall_leftcorner_visual" size="1.06 1.5 0.01" pos="-1.25 2.25 1.5" quat="0.653281 0.653281 0.270598 0.270598" type="box" contype="0" conaffinity="0" group="1" material="walls_mat"/>
    <geom name="wall_rightcorner_visual" size="1.06 1.5 0.01" pos="-1.25 -2.25 1.5" quat="0.653281 0.653281 -0.270598 -0.270598" type="box" contype="0" conaffinity="0" group="1" material="walls_mat"/>
    <geom name="wall_left_visual" size="1.75 1.5 0.01" pos="1.25 3 1.5" quat="0.707107 0.707107 0 0" type="box" contype="0" conaffinity="0" group="1" material="walls_mat"/>
    <geom name="wall_right_visual" size="1.75 1.5 0.01" pos="1.25 -3 1.5" quat="0.707107 -0.707107 0 0" type="box" contype="0" conaffinity="0" group="1" material="walls_mat"/>
    <geom name="wall_rear_visual" size="1.5 1.5 0.01" pos="-2 0 1.5" quat="0.5 0.5 0.5 0.5" type="box" contype="0" conaffinity="0" group="1" material="walls_mat"/>
    <geom name="wall_front_visual" size="3 1.5 0.01" pos="3 0 1.5" quat="0.5 0.5 -0.5 -0.5" type="box" contype="0" conaffinity="0" group="1" material="walls_mat"/>
    <camera name="frontview" pos="1.6 0 1.45" quat="0.560842 0.430646 0.430646 0.560842"/>
    <camera name="birdview" pos="-0.2 0 3" quat="0.707107 0 0 0.707107"/>
    <camera name="agentview" pos="0.598613 -4.39204e-09 1.59035" quat="0.638018 0.30485 0.30485 0.638018"/>
    <camera name="sideview" pos="-0.343427 1.28343 1.36191" quat="-0.3372 -0.200397 0.522052 0.757364"/>
    <light pos="1 1 1.5" dir="-0.19245 -0.19245 -0.96225" directional="true" castshadow="false"/>
    <body name="robot0_base" pos="-0.16 0.3 0.912">
      <inertial pos="0 0 0" mass="0" diaginertia="0 0 0"/>
      <geom name="robot0_g0_vis" type="mesh" contype="0" conaffinity="0" group="1" material="robot0_Black" mesh="robot0_base_vis_0"/>
      <geom name="robot0_g1_vis" type="mesh" contype="0" conaffinity="0" group="1" material="robot0_JointGrey" mesh="robot0_base_vis_1"/>
      <geom name="robot0_base_col" type="mesh" rgba="0 0.5 0 1" mesh="robot0_base"/>
      <camera name="robot0_robotview" pos="1 0 0.4" quat="0.653098 0.271041 0.271041 0.653098"/>
      <body name="robot0_shoulder_link" pos="0 0 0.163">
        <inertial pos="0 0 0" mass="3.7" diaginertia="0.0102675 0.0102675 0.00666"/>
        <joint name="robot0_shoulder_pan_joint" pos="0 0 0" axis="0 0 1" limited="true" range="-6.28319 6.28319" armature="5" damping="0.001" frictionloss="0.01"/>
        <geom name="robot0_g2_vis" type="mesh" contype="0" conaffinity="0" group="1" material="robot0_URBlue" mesh="robot0_shoulder_vis_0"/>
        <geom name="robot0_g3_vis" type="mesh" contype="0" conaffinity="0" group="1" material="robot0_Black" mesh="robot0_shoulder_vis_1"/>
        <geom name="robot0_g4_vis" type="mesh" contype="0" conaffinity="0" group="1" material="robot0_JointGrey" mesh="robot0_shoulder_vis_2"/>
        <geom name="robot0_shoulder_col" type="mesh" rgba="0 0.5 0 1" mesh="robot0_shoulder"/>
        <body name="robot0_upper_arm_link" pos="0 0.138 0" quat="0.707107 0 0.707107 0">
          <inertial pos="0 0 0.2125" mass="8.393" diaginertia="0.133886 0.133886 0.0151074"/>
          <joint name="robot0_shoulder_lift_joint" pos="0 0 0" axis="0 1 0" limited="true" range="-6.28319 6.28319" armature="2.5" damping="0.001" frictionloss="0.01"/>
          <geom name="robot0_g5_vis" type="mesh" contype="0" conaffinity="0" group="1" material="robot0_LinkGrey" mesh="robot0_upperarm_vis_0"/>
          <geom name="robot0_g6_vis" type="mesh" contype="0" conaffinity="0" group="1" material="robot0_Black" mesh="robot0_upperarm_vis_1"/>
          <geom name="robot0_g7_vis" type="mesh" contype="0" conaffinity="0" group="1" material="robot0_JointGrey" mesh="robot0_upperarm_vis_2"/>
          <geom name="robot0_g8_vis" type="mesh" contype="0" conaffinity="0" group="1" material="robot0_URBlue" mesh="robot0_upperarm_vis_3"/>
          <geom name="robot0_upperarm_col" type="mesh" rgba="0 0.5 0 1" mesh="robot0_upperarm"/>
          <body name="robot0_forearm_link" pos="0 -0.131 0.425">
            <inertial pos="0 0 0.196" mass="2.275" diaginertia="0.0311796 0.0311796 0.004095"/>
            <joint name="robot0_elbow_joint" pos="0 0 0" axis="0 1 0" limited="true" range="-3.14159 3.14159" armature="1.66667" damping="0.001" frictionloss="0.01"/>
            <geom name="robot0_g9_vis" type="mesh" contype="0" conaffinity="0" group="1" material="robot0_URBlue" mesh="robot0_forearm_vis_0"/>
            <geom name="robot0_g10_vis" type="mesh" contype="0" conaffinity="0" group="1" material="robot0_LinkGrey" mesh="robot0_forearm_vis_1"/>
            <geom name="robot0_g11_vis" type="mesh" contype="0" conaffinity="0" group="1" material="robot0_Black" mesh="robot0_forearm_vis_2"/>
            <geom name="robot0_g12_vis" type="mesh" contype="0" conaffinity="0" group="1" material="robot0_JointGrey" mesh="robot0_forearm_vis_3"/>
            <geom name="robot0_forearm_col" type="mesh" rgba="0 0.5 0 1" mesh="robot0_forearm"/>
            <body name="robot0_wrist_1_link" pos="0 0 0.392" quat="0.707107 0 0.707107 0">
              <inertial pos="0 0.127 0" mass="1.219" diaginertia="0.0025599 0.0025599 0.0021942"/>
              <joint name="robot0_wrist_1_joint" pos="0 0 0" axis="0 1 0" limited="true" range="-6.28319 6.28319" armature="1.25" damping="0.001" frictionloss="0.01"/>
              <geom name="robot0_g13_vis" type="mesh" contype="0" conaffinity="0" group="1" material="robot0_Black" mesh="robot0_wrist1_vis_0"/>
              <geom name="robot0_g14_vis" type="mesh" contype="0" conaffinity="0" group="1" material="robot0_URBlue" mesh="robot0_wrist1_vis_1"/>
              <geom name="robot0_g15_vis" type="mesh" contype="0" conaffinity="0" group="1" material="robot0_JointGrey" mesh="robot0_wrist1_vis_2"/>
              <geom name="robot0_wrist1_col" type="mesh" rgba="0 0.5 0 1" mesh="robot0_wrist1"/>
              <body name="robot0_wrist_2_link" pos="0 0.127 0">
                <inertial pos="0 0 0.1" mass="1.219" diaginertia="0.0025599 0.0025599 0.0021942"/>
                <joint name="robot0_wrist_2_joint" pos="0 0 0" axis="0 0 1" limited="true" range="-6.28319 6.28319" armature="1" damping="0.001" frictionloss="0.01"/>
                <geom name="robot0_g16_vis" type="mesh" contype="0" conaffinity="0" group="1" material="robot0_Black" mesh="robot0_wrist2_vis_0"/>
                <geom name="robot0_g17_vis" type="mesh" contype="0" conaffinity="0" group="1" material="robot0_URBlue" mesh="robot0_wrist2_vis_1"/>
                <geom name="robot0_g18_vis" type="mesh" contype="0" conaffinity="0" group="1" material="robot0_JointGrey" mesh="robot0_wrist2_vis_2"/>
                <geom name="robot0_wrist2_col" type="mesh" rgba="0 0.5 0 1" mesh="robot0_wrist2"/>
                <body name="robot0_wrist_3_link" pos="0 0 0.1">
                  <inertial pos="0 0.0771683 0" quat="0.707107 0 0 0.707107" mass="0.1889" diaginertia="0.000132134 9.90863e-05 9.90863e-05"/>
                  <joint name="robot0_wrist_3_joint" pos="0 0 0" axis="0 1 0" limited="true" range="-6.28319 6.28319" armature="0.833333" damping="0.001" frictionloss="0.01"/>
                  <geom name="robot0_g19_vis" type="mesh" contype="0" conaffinity="0" group="1" material="robot0_LinkGrey" mesh="robot0_wrist3_vis"/>
                  <geom name="robot0_wrist3_col" type="mesh" rgba="0 0.5 0 1" mesh="robot0_wrist3"/>
                  <geom name="robot0_wrist3_col2" size="0.005 0.005 0.005" pos="0 0.09 0" quat="0.707107 0 0 0.707107" type="box" rgba="0 0.5 0 1"/>
                  <body name="robot0_right_hand" pos="0 0.098 0" quat="0.707107 -0.707107 0 0">
                    <camera name="robot0_eye_in_hand" pos="0.05 0 0" quat="0 0.707107 0.707107 0" fovy="75"/>
                    <body name="gripper0_robotiq_85_adapter_link">
                      <inertial pos="0 0 0" mass="0.01" diaginertia="0.001 0.001 0.001"/>
                      <geom name="gripper0_hand_visual" type="mesh" contype="0" conaffinity="0" group="1" rgba="0.1 0.1 0.1 1" mesh="gripper0_robotiq_arg2f_base_link"/>
                      <geom name="gripper0_hand_collision" type="mesh" rgba="0 0 0.5 1" mesh="gripper0_robotiq_arg2f_base_link"/>
                      <site name="gripper0_ft_frame" pos="0 0 0" size="1e-08" group="1" rgba="1 0 0 -1"/>
                      <body name="gripper0_eef" pos="0 0 0.145" quat="0.707107 0 0 -0.707107">
                        <site name="gripper0_grip_site" pos="0 0 0" size="1e-08" group="1" rgba="1 0 0 -0.5"/>
                        <site name="gripper0_ee_x" pos="0.1 0 0" quat="0.707105 0 0.707108 0" size="1e-08 1e-08" group="1" type="cylinder" rgba="1 0 0 0"/>
                        <site name="gripper0_ee_y" pos="0 0.1 0" quat="0.707105 0.707108 0 0" size="1e-08 1e-08" group="1" type="cylinder" rgba="0 1 0 0"/>
                        <site name="gripper0_ee_z" pos="0 0 0.1" size="1e-08 1e-08" group="1" type="cylinder" rgba="0 0 1 0"/>
                        <site name="gripper0_grip_site_cylinder" pos="0 0 0" size="1e-08 1e-08" group="1" type="cylinder" rgba="0 1 0 -0.3"/>
                      </body>
                      <body name="gripper0_left_outer_knuckle" pos="0 -0.0306011 0.054904" quat="0 0 0 1">
                        <inertial pos="0.000163875 0.0554825 -0.0100755" quat="0.920541 0.390623 -0.00362953 0.00231744" mass="0.0311462" diaginertia="5.11372e-05 4.89464e-05 4.95906e-06"/>
                        <joint name="gripper0_finger_joint" pos="0 0 0" axis="1 0 0" limited="true" range="0 0.8"/>
                        <geom name="gripper0_left_outer_knuckle_visual" type="mesh" contype="0" conaffinity="0" group="1" rgba="0.792157 0.819608 0.933333 1" mesh="gripper0_robotiq_arg2f_85_outer_knuckle_vis"/>
                        <geom name="gripper0_left_outer_knuckle_collision" type="mesh" solref="0.01 0.25" rgba="0 0 0.5 1" mesh="gripper0_robotiq_arg2f_85_outer_knuckle"/>
                        <geom name="gripper0_left_outer_finger_visual" pos="0 0.0315 -0.0041" quat="1 0 0 0" type="mesh" contype="0" conaffinity="0" group="1" rgba="0.1 0.1 0.1 1" mesh="gripper0_robotiq_arg2f_85_outer_finger_vis"/>
                        <geom name="gripper0_left_outer_finger_collision" pos="0 0.0315 -0.0041" quat="1 0 0 0" type="mesh" solref="0.01 0.25" rgba="0 0 0.5 1" mesh="gripper0_robotiq_arg2f_85_outer_finger"/>
                        <body name="gripper0_left_inner_finger" pos="0 0.0376 0.043">
                          <inertial pos="0.000199506 0.0032692 0.00175282" quat="0.933621 0.35825 -0.00273441 0.00104851" mass="0.0156391" diaginertia="1.57977e-05 1.51089e-05 1.4647e-06"/>
                          <joint name="gripper0_left_inner_finger_joint" pos="0 0 0" axis="1 0 0" limited="true" range="-0.8757 0.8757"/>
                          <geom name="gripper0_left_inner_finger_visual" type="mesh" contype="0" conaffinity="0" group="1" rgba="0.1 0.1 0.1 1" mesh="gripper0_robotiq_arg2f_85_inner_finger_vis"/>
                          <geom name="gripper0_left_inner_finger_collision" type="mesh" solref="0.01 0.25" rgba="0 0 0.5 1" mesh="gripper0_robotiq_arg2f_85_inner_finger"/>
                          <geom name="gripper0_left_fingertip_visual" size="0.011 0.003175 0.01875" pos="0 -0.0220203 0.03242" type="box" contype="0" conaffinity="0" group="1" rgba="0.9 0.9 0.9 1"/>
                          <geom name="gripper0_left_fingertip_collision" size="0.011 0.003175 0.01875" pos="0 -0.0220203 0.03242" type="box" solref="0.01 0.25" rgba="0 0 0.5 1"/>
                          <geom name="gripper0_left_fingerpad_collision" size="0.01 0.001 0.01675" pos="0 -0.0245203 0.03242" type="box" rgba="0 0 0.5 1"/>
                        </body>
                      </body>
                      <body name="gripper0_left_inner_knuckle" pos="0 -0.0127 0.06142" quat="0 0 0 1">
                        <inertial pos="0.000123012 0.0507851 0.00103969" quat="0.497203 0.502496 -0.507943 0.492221" mass="0.0271177" diaginertia="2.83809e-05 2.61936e-05 2.81319e-06"/>
                        <joint name="gripper0_left_inner_knuckle_joint" pos="0 0 0" axis="1 0 0" limited="true" range="0 0.8757"/>
                        <geom name="gripper0_left_inner_knuckle_visual" type="mesh" contype="0" conaffinity="0" group="1" rgba="0.1 0.1 0.1 1" mesh="gripper0_robotiq_arg2f_85_inner_knuckle_vis"/>
                        <geom name="gripper0_left_inner_knuckle_collision" type="mesh" rgba="0 0 0.5 1" mesh="gripper0_robotiq_arg2f_85_inner_knuckle"/>
                      </body>
                      <body name="gripper0_right_outer_knuckle" pos="0 0.0306011 0.054904">
                        <inertial pos="0.000163875 0.0554825 -0.0100755" quat="0.920541 0.390623 -0.00362953 0.00231744" mass="0.0311462" diaginertia="5.11372e-05 4.89464e-05 4.95906e-06"/>
                        <joint name="gripper0_right_outer_knuckle_joint" pos="0 0 0" axis="1 0 0" limited="true" range="0 0.8"/>
                        <geom name="gripper0_right_outer_knuckle_visual" type="mesh" contype="0" conaffinity="0" group="1" rgba="0.792157 0.819608 0.933333 1" mesh="gripper0_robotiq_arg2f_85_outer_knuckle_vis"/>
                        <geom name="gripper0_right_outer_knuckle_collision" type="mesh" solref="0.01 0.25" rgba="0 0 0.5 1" mesh="gripper0_robotiq_arg2f_85_outer_knuckle"/>
                        <geom name="gripper0_right_outer_finger_visual" pos="0 0.0315 -0.0041" quat="1 0 0 0" type="mesh" contype="0" conaffinity="0" group="1" rgba="0.1 0.1 0.1 1" mesh="gripper0_robotiq_arg2f_85_outer_finger_vis"/>
                        <geom name="gripper0_right_outer_finger_collision" pos="0 0.0315 -0.0041" quat="1 0 0 0" type="mesh" solref="0.01 0.25" rgba="0 0 0.5 1" mesh="gripper0_robotiq_arg2f_85_outer_finger"/>
                        <body name="gripper0_right_inner_finger" pos="0 0.0376 0.043">
                          <inertial pos="0.000199506 0.0032692 0.00175282" quat="0.933621 0.35825 -0.00273441 0.00104851" mass="0.0156391" diaginertia="1.57977e-05 1.51089e-05 1.4647e-06"/>
                          <joint name="gripper0_right_inner_finger_joint" pos="0 0 0" axis="1 0 0" limited="true" range="-0.8757 0.8757"/>
                          <geom name="gripper0_right_inner_finger_visual" type="mesh" contype="0" conaffinity="0" group="1" rgba="0.1 0.1 0.1 1" mesh="gripper0_robotiq_arg2f_85_inner_finger_vis"/>
                          <geom name="gripper0_right_inner_finger_collision" type="mesh" solref="0.01 0.25" rgba="0 0 0.5 1" mesh="gripper0_robotiq_arg2f_85_inner_finger"/>
                          <geom name="gripper0_right_fingertip_visual" size="0.011 0.003175 0.01875" pos="0 -0.0220203 0.03242" type="box" contype="0" conaffinity="0" group="1" rgba="0.9 0.9 0.9 1"/>
                          <geom name="gripper0_right_fingertip_collision" size="0.011 0.003175 0.01875" pos="0 -0.0220203 0.03242" type="box" solref="0.01 0.25" rgba="0 0 0.5 1"/>
                          <geom name="gripper0_right_fingerpad_collision" size="0.01 0.001 0.01675" pos="0 -0.0245203 0.03242" type="box" rgba="0 0 0.5 1"/>
                        </body>
                      </body>
                      <body name="gripper0_right_inner_knuckle" pos="0 0.0127 0.06142">
                        <inertial pos="0.000123012 0.0507851 0.00103969" quat="0.497203 0.502496 -0.507943 0.492221" mass="0.0271177" diaginertia="2.83809e-05 2.61936e-05 2.81319e-06"/>
                        <joint name="gripper0_right_inner_knuckle_joint" pos="0 0 0" axis="1 0 0" limited="true" range="0 0.8757"/>
                        <geom name="gripper0_right_inner_knuckle_visual" type="mesh" contype="0" conaffinity="0" group="1" rgba="0.1 0.1 0.1 1" mesh="gripper0_robotiq_arg2f_85_inner_knuckle_vis"/>
                        <geom name="gripper0_right_inner_knuckle_collision" type="mesh" rgba="0 0 0.5 1" mesh="gripper0_robotiq_arg2f_85_inner_knuckle"/>
                      </body>
                    </body>
                  </body>
                </body>
              </body>
            </body>
          </body>
        </body>
      </body>
      <body name="mount0_base" pos="0 0 0.01">
        <body name="mount0_controller_box">
          <inertial pos="-0.325 0 -0.38" mass="46.64" diaginertia="1.71363 1.27988 0.809981"/>
          <geom name="mount0_controller_box_col" size="0.11 0.2 0.265" pos="-0.325 0 -0.38" type="box" rgba="0.5 0.5 0 1"/>
        </body>
        <body name="mount0_pedestal_feet">
          <inertial pos="-0.1225 0 -0.758" mass="167.09" diaginertia="8.16095 9.59375 15.0785"/>
          <geom name="mount0_pedestal_feet_col" size="0.385 0.35 0.155" pos="-0.1225 0 -0.758" type="box" rgba="0.5 0.5 0 1"/>
        </body>
        <body name="mount0_torso">
          <inertial pos="0 0 0" mass="0.0001" diaginertia="1e-08 1e-08 1e-08"/>
          <geom name="mount0_torso_vis" size="0.05 0.05 0.05" pos="0 0 -0.05" type="box" contype="0" conaffinity="0" group="1" rgba="0.2 0.2 0.2 1"/>
        </body>
        <body name="mount0_pedestal">
          <inertial pos="0 0 0" quat="0.659267 -0.259505 -0.260945 0.655692" mass="60.864" diaginertia="6.0869 5.81635 4.20915"/>
          <geom name="mount0_pedestal_vis" type="mesh" contype="0" conaffinity="0" group="1" rgba="0.2 0.2 0.2 1" mesh="mount0_pedestal"/>
          <geom name="mount0_pedestal_col" size="0.18 0.31" pos="-0.02 0 -0.29" type="cylinder" rgba="0.5 0.5 0 1"/>
        </body>
      </body>
    </body>
    <body name="train-microwave-1_main" pos="0.64 0.3 0.8">
      <geom name="train-microwave-1_g0" pos="0 0 0" quat="0.5 0.5 -0.5 -0.5" type="mesh" contype="0" conaffinity="0" rgba="0.5 0 0 1" mesh="train-microwave-1_original-12"/>
      <geom name="train-microwave-1_g1" pos="0 0 0" quat="0.5 0.5 -0.5 -0.5" type="mesh" contype="0" conaffinity="0" rgba="0.5 0 0 1" mesh="train-microwave-1_new-4"/>
      <geom name="train-microwave-1_g2" pos="0 0 0" quat="0.5 0.5 -0.5 -0.5" type="mesh" contype="0" conaffinity="0" rgba="0.5 0 0 1" mesh="train-microwave-1_original-49"/>
      <geom name="train-microwave-1_g3" quat="0.5 0.5 -0.5 -0.5" type="mesh" contype="0" conaffinity="0" rgba="0.5 0 0 1" mesh="train-microwave-1_original-51"/>
      <geom name="train-microwave-1_g4" pos="0 0 0" quat="0.5 0.5 -0.5 -0.5" type="mesh" contype="0" conaffinity="0" rgba="0.5 0 0 1" mesh="train-microwave-1_original-1"/>
      <geom name="train-microwave-1_g5" quat="0.5 0.5 -0.5 -0.5" type="mesh" contype="0" conaffinity="0" rgba="0.5 0 0 1" mesh="train-microwave-1_original-50"/>
      <geom name="train-microwave-1_g6" pos="0 0 0" quat="0.5 0.5 -0.5 -0.5" type="mesh" contype="0" conaffinity="0" rgba="0.5 0 0 1" mesh="train-microwave-1_new-3"/>
      <geom name="train-microwave-1_g7" pos="0 0 0" quat="0.5 0.5 -0.5 -0.5" type="mesh" contype="0" conaffinity="0" rgba="0.5 0 0 1" mesh="train-microwave-1_new-2"/>
      <geom name="train-microwave-1_g8" pos="0 0 0" quat="0.5 0.5 -0.5 -0.5" type="mesh" contype="0" conaffinity="0" rgba="0.5 0 0 1" mesh="train-microwave-1_new-1"/>
      <geom name="train-microwave-1_g9" pos="0 0 0" quat="0.5 0.5 -0.5 -0.5" type="mesh" contype="0" conaffinity="0" rgba="0.5 0 0 1" mesh="train-microwave-1_new-0"/>
      <geom name="train-microwave-1_g0_visual" pos="0 0 0" quat="0.5 0.5 -0.5 -0.5" type="mesh" contype="0" conaffinity="0" group="1" mass="0" mesh="train-microwave-1_original-12"/>
      <geom name="train-microwave-1_g1_visual" pos="0 0 0" quat="0.5 0.5 -0.5 -0.5" type="mesh" contype="0" conaffinity="0" group="1" mass="0" mesh="train-microwave-1_new-4"/>
      <geom name="train-microwave-1_g2_visual" pos="0 0 0" quat="0.5 0.5 -0.5 -0.5" type="mesh" contype="0" conaffinity="0" group="1" mass="0" mesh="train-microwave-1_original-49"/>
      <geom name="train-microwave-1_g3_visual" quat="0.5 0.5 -0.5 -0.5" type="mesh" contype="0" conaffinity="0" group="1" mass="0" mesh="train-microwave-1_original-51"/>
      <geom name="train-microwave-1_g4_visual" pos="0 0 0" quat="0.5 0.5 -0.5 -0.5" type="mesh" contype="0" conaffinity="0" group="1" mass="0" mesh="train-microwave-1_original-1"/>
      <geom name="train-microwave-1_g5_visual" quat="0.5 0.5 -0.5 -0.5" type="mesh" contype="0" conaffinity="0" group="1" mass="0" mesh="train-microwave-1_original-50"/>
      <geom name="train-microwave-1_g6_visual" pos="0 0 0" quat="0.5 0.5 -0.5 -0.5" type="mesh" contype="0" conaffinity="0" group="1" mass="0" mesh="train-microwave-1_new-3"/>
      <geom name="train-microwave-1_g7_visual" pos="0 0 0" quat="0.5 0.5 -0.5 -0.5" type="mesh" contype="0" conaffinity="0" group="1" mass="0" mesh="train-microwave-1_new-2"/>
      <geom name="train-microwave-1_g8_visual" pos="0 0 0" quat="0.5 0.5 -0.5 -0.5" type="mesh" contype="0" conaffinity="0" group="1" mass="0" mesh="train-microwave-1_new-1"/>
      <geom name="train-microwave-1_g9_visual" pos="0 0 0" quat="0.5 0.5 -0.5 -0.5" type="mesh" contype="0" conaffinity="0" group="1" mass="0" mesh="train-microwave-1_new-0"/>
      <site name="train-microwave-1_default_site" pos="0 0 0" size="1e-08" rgba="1 0 0 0"/>
      <body name="train-microwave-1_link_0" pos="-0.107765 0.185636 0" quat="0.5 0.5 -0.5 -0.5">
        <inertial pos="0.124449 0.00499332 0.0896772" quat="0.00349468 0.499467 -0.00703786 0.866297" mass="72.4061" diaginertia="9.0744 5.85664 3.30306"/>
        <joint name="train-microwave-1_joint_0" pos="0 0 0" axis="0 -1 0" limited="true" range="-0.523599 1.39626"/>
        <geom name="train-microwave-1_panel" pos="0.185636 0 -0.107765" quat="1 0 0 0" type="mesh" rgba="0.5 0 0 1" mesh="train-microwave-1_new-6"/>
        <geom name="train-microwave-1_panel-2" pos="0.185636 0 -0.107765" quat="1 0 0 0" type="mesh" rgba="0.5 0 0 1" mesh="train-microwave-1_new-5"/>
        <geom name="train-microwave-1_g12" pos="0.185636 0 -0.107765" quat="1 0 0 0" type="mesh" rgba="0.5 0 0 1" mesh="train-microwave-1_original-3"/>
        <geom name="train-microwave-1_g13" pos="0.185636 0 -0.107765" quat="1 0 0 0" type="mesh" rgba="0.5 0 0 1" mesh="train-microwave-1_original-4"/>
        <geom name="train-microwave-1_panel_visual" pos="0.185636 0 -0.107765" quat="1 0 0 0" type="mesh" contype="0" conaffinity="0" group="1" mass="0" mesh="train-microwave-1_new-6"/>
        <geom name="train-microwave-1_panel-2_visual" pos="0.185636 0 -0.107765" quat="1 0 0 0" type="mesh" contype="0" conaffinity="0" group="1" mass="0" mesh="train-microwave-1_new-5"/>
        <geom name="train-microwave-1_g12_visual" pos="0.185636 0 -0.107765" quat="1 0 0 0" type="mesh" contype="0" conaffinity="0" group="1" mass="0" mesh="train-microwave-1_original-3"/>
        <geom name="train-microwave-1_g13_visual" pos="0.185636 0 -0.107765" quat="1 0 0 0" type="mesh" contype="0" conaffinity="0" group="1" mass="0" mesh="train-microwave-1_original-4"/>
      </body>
      <body name="train-microwave-1_link_1" pos="-0.136735 -0.162565 -0.068721" quat="0.5 0.5 -0.5 -0.5">
        <inertial pos="0.015758 0.023488 0.00148276" quat="0.416789 0.571373 -0.416729 0.571101" mass="0.0153622" diaginertia="5.42181e-06 2.78238e-06 2.76854e-06"/>
        <joint name="train-microwave-1_joint_1" pos="0 0 0" axis="0 0 -1" type="slide" limited="true" range="0 0.0012"/>
        <geom name="train-microwave-1_g14" pos="-0.162565 0.068721 -0.136735" quat="1 0 0 0" type="mesh" rgba="0.5 0 0 1" mesh="train-microwave-1_original-41"/>
        <geom name="train-microwave-1_g15" pos="-0.162565 0.068721 -0.136735" quat="1 0 0 0" type="mesh" rgba="0.5 0 0 1" mesh="train-microwave-1_original-36"/>
        <geom name="train-microwave-1_g14_visual" pos="-0.162565 0.068721 -0.136735" quat="1 0 0 0" type="mesh" contype="0" conaffinity="0" group="1" mass="0" mesh="train-microwave-1_original-41"/>
        <geom name="train-microwave-1_g15_visual" pos="-0.162565 0.068721 -0.136735" quat="1 0 0 0" type="mesh" contype="0" conaffinity="0" group="1" mass="0" mesh="train-microwave-1_original-36"/>
      </body>
      <body name="train-microwave-1_link_2" pos="-0.136735 -0.162565 -0.068721" quat="0.5 0.5 -0.5 -0.5">
        <inertial pos="-0.00565305 0.0234839 0.001477" quat="0.523586 0.475286 -0.523487 0.475312" mass="0.0152598" diaginertia="5.40253e-06 2.76766e-06 2.76238e-06"/>
        <joint name="train-microwave-1_joint_2" pos="0 0 0" axis="0 0 -1" type="slide" limited="true" range="0 0.0012"/>
        <geom name="train-microwave-1_g16" pos="-0.162565 0.068721 -0.136735" quat="1 0 0 0" type="mesh" rgba="0.5 0 0 1" mesh="train-microwave-1_original-35"/>
        <geom name="train-microwave-1_g17" pos="-0.162565 0.068721 -0.136735" quat="1 0 0 0" type="mesh" rgba="0.5 0 0 1" mesh="train-microwave-1_original-19"/>
        <geom name="train-microwave-1_g16_visual" pos="-0.162565 0.068721 -0.136735" quat="1 0 0 0" type="mesh" contype="0" conaffinity="0" group="1" mass="0" mesh="train-microwave-1_original-35"/>
        <geom name="train-microwave-1_g17_visual" pos="-0.162565 0.068721 -0.136735" quat="1 0 0 0" type="mesh" contype="0" conaffinity="0" group="1" mass="0" mesh="train-microwave-1_original-19"/>
      </body>
      <body name="train-microwave-1_link_3" pos="-0.136735 -0.162565 -0.068721" quat="0.5 0.5 -0.5 -0.5">
        <inertial pos="-0.0270896 0.0234803 0.00148585" quat="0.511133 0.489369 -0.510207 0.488824" mass="0.0154119" diaginertia="5.43794e-06 2.79688e-06 2.77117e-06"/>
        <joint name="train-microwave-1_joint_3" pos="0 0 0" axis="0 0 -1" type="slide" limited="true" range="0 0.0012"/>
        <geom name="train-microwave-1_g18" pos="-0.162565 0.068721 -0.136735" quat="1 0 0 0" type="mesh" rgba="0.5 0 0 1" mesh="train-microwave-1_original-42"/>
        <geom name="train-microwave-1_g19" pos="-0.162565 0.068721 -0.136735" quat="1 0 0 0" type="mesh" rgba="0.5 0 0 1" mesh="train-microwave-1_original-34"/>
        <geom name="train-microwave-1_g18_visual" pos="-0.162565 0.068721 -0.136735" quat="1 0 0 0" type="mesh" contype="0" conaffinity="0" group="1" mass="0" mesh="train-microwave-1_original-42"/>
        <geom name="train-microwave-1_g19_visual" pos="-0.162565 0.068721 -0.136735" quat="1 0 0 0" type="mesh" contype="0" conaffinity="0" group="1" mass="0" mesh="train-microwave-1_original-34"/>
      </body>
      <body name="train-microwave-1_link_4" pos="-0.136735 -0.162565 -0.068721" quat="0.5 0.5 -0.5 -0.5">
        <inertial pos="0.0157651 0.0434799 0.00147585" quat="0.433322 0.558723 -0.433633 0.55859" mass="0.015244" diaginertia="5.40095e-06 2.76746e-06 2.76057e-06"/>
        <joint name="train-microwave-1_joint_4" pos="0 0 0" axis="0 0 -1" type="slide" limited="true" range="0 0.0012"/>
        <geom name="train-microwave-1_g20" pos="-0.162565 0.068721 -0.136735" quat="1 0 0 0" type="mesh" rgba="0.5 0 0 1" mesh="train-microwave-1_original-31"/>
        <geom name="train-microwave-1_g21" pos="-0.162565 0.068721 -0.136735" quat="1 0 0 0" type="mesh" rgba="0.5 0 0 1" mesh="train-microwave-1_original-18"/>
        <geom name="train-microwave-1_g20_visual" pos="-0.162565 0.068721 -0.136735" quat="1 0 0 0" type="mesh" contype="0" conaffinity="0" group="1" mass="0" mesh="train-microwave-1_original-31"/>
        <geom name="train-microwave-1_g21_visual" pos="-0.162565 0.068721 -0.136735" quat="1 0 0 0" type="mesh" contype="0" conaffinity="0" group="1" mass="0" mesh="train-microwave-1_original-18"/>
      </body>
      <body name="train-microwave-1_link_5" pos="-0.136735 -0.162565 -0.068721" quat="0.5 0.5 -0.5 -0.5">
        <inertial pos="-0.00565224 0.0434718 0.0014766" quat="0.50045 0.499561 -0.500384 0.499604" mass="0.0152543" diaginertia="5.40253e-06 2.76929e-06 2.76059e-06"/>
        <joint name="train-microwave-1_joint_5" pos="0 0 0" axis="0 0 -1" type="slide" limited="true" range="0 0.0012"/>
        <geom name="train-microwave-1_g22" pos="-0.162565 0.068721 -0.136735" quat="1 0 0 0" type="mesh" rgba="0.5 0 0 1" mesh="train-microwave-1_original-17"/>
        <geom name="train-microwave-1_g23" pos="-0.162565 0.068721 -0.136735" quat="1 0 0 0" type="mesh" rgba="0.5 0 0 1" mesh="train-microwave-1_original-33"/>
        <geom name="train-microwave-1_g22_visual" pos="-0.162565 0.068721 -0.136735" quat="1 0 0 0" type="mesh" contype="0" conaffinity="0" group="1" mass="0" mesh="train-microwave-1_original-17"/>
        <geom name="train-microwave-1_g23_visual" pos="-0.162565 0.068721 -0.136735" quat="1 0 0 0" type="mesh" contype="0" conaffinity="0" group="1" mass="0" mesh="train-microwave-1_original-33"/>
      </body>
      <body name="train-microwave-1_link_6" pos="-0.136735 -0.162565 -0.068721" quat="0.5 0.5 -0.5 -0.5">
        <inertial pos="-0.027067 0.0435009 0.00147529" quat="0.538897 0.4578 -0.539781 0.456777" mass="0.0152383" diaginertia="5.41307e-06 2.78393e-06 2.75593e-06"/>
        <joint name="train-microwave-1_joint_6" pos="0 0 0" axis="0 0 -1" type="slide" limited="true" range="0 0.0012"/>
        <geom name="train-microwave-1_g24" pos="-0.162565 0.068721 -0.136735" quat="1 0 0 0" type="mesh" rgba="0.5 0 0 1" mesh="train-microwave-1_original-32"/>
        <geom name="train-microwave-1_g25" pos="-0.162565 0.068721 -0.136735" quat="1 0 0 0" type="mesh" rgba="0.5 0 0 1" mesh="train-microwave-1_original-16"/>
        <geom name="train-microwave-1_g24_visual" pos="-0.162565 0.068721 -0.136735" quat="1 0 0 0" type="mesh" contype="0" conaffinity="0" group="1" mass="0" mesh="train-microwave-1_original-32"/>
        <geom name="train-microwave-1_g25_visual" pos="-0.162565 0.068721 -0.136735" quat="1 0 0 0" type="mesh" contype="0" conaffinity="0" group="1" mass="0" mesh="train-microwave-1_original-16"/>
      </body>
      <body name="train-microwave-1_link_7" pos="-0.136735 -0.162565 -0.068721" quat="0.5 0.5 -0.5 -0.5">
        <inertial pos="0.0157606 0.0634572 0.00147636" quat="0.498386 0.501707 -0.498157 0.501738" mass="0.0152511" diaginertia="5.40133e-06 2.76679e-06 2.76181e-06"/>
        <joint name="train-microwave-1_joint_7" pos="0 0 0" axis="0 0 -1" type="slide" limited="true" range="0 0.0012"/>
        <geom name="train-microwave-1_g26" pos="-0.162565 0.068721 -0.136735" quat="1 0 0 0" type="mesh" rgba="0.5 0 0 1" mesh="train-microwave-1_original-15"/>
        <geom name="train-microwave-1_g27" pos="-0.162565 0.068721 -0.136735" quat="1 0 0 0" type="mesh" rgba="0.5 0 0 1" mesh="train-microwave-1_original-30"/>
        <geom name="train-microwave-1_g26_visual" pos="-0.162565 0.068721 -0.136735" quat="1 0 0 0" type="mesh" contype="0" conaffinity="0" group="1" mass="0" mesh="train-microwave-1_original-15"/>
        <geom name="train-microwave-1_g27_visual" pos="-0.162565 0.068721 -0.136735" quat="1 0 0 0" type="mesh" contype="0" conaffinity="0" group="1" mass="0" mesh="train-microwave-1_original-30"/>
      </body>
      <body name="train-microwave-1_link_8" pos="-0.136735 -0.162565 -0.068721" quat="0.5 0.5 -0.5 -0.5">
        <inertial pos="-0.00564204 0.0634521 0.00147657" quat="0.460979 0.535865 -0.460969 0.536521" mass="0.0152547" diaginertia="5.40482e-06 2.77216e-06 2.75997e-06"/>
        <joint name="train-microwave-1_joint_8" pos="0 0 0" axis="0 0 -1" type="slide" limited="true" range="0 0.0012"/>
        <geom name="train-microwave-1_g28" pos="-0.162565 0.068721 -0.136735" quat="1 0 0 0" type="mesh" rgba="0.5 0 0 1" mesh="train-microwave-1_original-14"/>
        <geom name="train-microwave-1_g29" pos="-0.162565 0.068721 -0.136735" quat="1 0 0 0" type="mesh" rgba="0.5 0 0 1" mesh="train-microwave-1_original-29"/>
        <geom name="train-microwave-1_g28_visual" pos="-0.162565 0.068721 -0.136735" quat="1 0 0 0" type="mesh" contype="0" conaffinity="0" group="1" mass="0" mesh="train-microwave-1_original-14"/>
        <geom name="train-microwave-1_g29_visual" pos="-0.162565 0.068721 -0.136735" quat="1 0 0 0" type="mesh" contype="0" conaffinity="0" group="1" mass="0" mesh="train-microwave-1_original-29"/>
      </body>
      <body name="train-microwave-1_link_9" pos="-0.136735 -0.162565 -0.068721" quat="0.5 0.5 -0.5 -0.5">
        <inertial pos="-0.0270596 0.0634584 0.00147068" quat="0.493278 0.506366 -0.493456 0.506726" mass="0.0151735" diaginertia="5.39223e-06 2.76187e-06 2.75547e-06"/>
        <joint name="train-microwave-1_joint_9" pos="0 0 0" axis="0 0 -1" type="slide" limited="true" range="0 0.0012"/>
        <geom name="train-microwave-1_g30" pos="-0.162565 0.068721 -0.136735" quat="1 0 0 0" type="mesh" rgba="0.5 0 0 1" mesh="train-microwave-1_original-40"/>
        <geom name="train-microwave-1_g31" pos="-0.162565 0.068721 -0.136735" quat="1 0 0 0" type="mesh" rgba="0.5 0 0 1" mesh="train-microwave-1_original-13"/>
        <geom name="train-microwave-1_g30_visual" pos="-0.162565 0.068721 -0.136735" quat="1 0 0 0" type="mesh" contype="0" conaffinity="0" group="1" mass="0" mesh="train-microwave-1_original-40"/>
        <geom name="train-microwave-1_g31_visual" pos="-0.162565 0.068721 -0.136735" quat="1 0 0 0" type="mesh" contype="0" conaffinity="0" group="1" mass="0" mesh="train-microwave-1_original-13"/>
      </body>
      <body name="train-microwave-1_link_10" pos="-0.136735 -0.162565 -0.068721" quat="0.5 0.5 -0.5 -0.5">
        <inertial pos="0.0157729 0.083445 0.00147703" quat="0.476989 0.52168 -0.477166 0.522153" mass="0.0152608" diaginertia="5.40687e-06 2.77474e-06 2.75963e-06"/>
        <joint name="train-microwave-1_joint_10" pos="0 0 0" axis="0 0 -1" type="slide" limited="true" range="0 0.0012"/>
        <geom name="train-microwave-1_g32" pos="-0.162565 0.068721 -0.136735" quat="1 0 0 0" type="mesh" rgba="0.5 0 0 1" mesh="train-microwave-1_original-39"/>
        <geom name="train-microwave-1_g33" pos="-0.162565 0.068721 -0.136735" quat="1 0 0 0" type="mesh" rgba="0.5 0 0 1" mesh="train-microwave-1_original-22"/>
        <geom name="train-microwave-1_g32_visual" pos="-0.162565 0.068721 -0.136735" quat="1 0 0 0" type="mesh" contype="0" conaffinity="0" group="1" mass="0" mesh="train-microwave-1_original-39"/>
        <geom name="train-microwave-1_g33_visual" pos="-0.162565 0.068721 -0.136735" quat="1 0 0 0" type="mesh" contype="0" conaffinity="0" group="1" mass="0" mesh="train-microwave-1_original-22"/>
      </body>
      <body name="train-microwave-1_link_11" pos="-0.136735 -0.162565 -0.068721" quat="0.5 0.5 -0.5 -0.5">
        <inertial pos="-0.0056418 0.0834357 0.00148107" quat="0.515069 0.484096 -0.515002 0.4849" mass="0.015318" diaginertia="5.42126e-06 2.78827e-06 2.76198e-06"/>
        <joint name="train-microwave-1_joint_11" pos="0 0 0" axis="0 0 -1" type="slide" limited="true" range="0 0.0012"/>
        <geom name="train-microwave-1_g34" pos="-0.162565 0.068721 -0.136735" quat="1 0 0 0" type="mesh" rgba="0.5 0 0 1" mesh="train-microwave-1_original-20"/>
        <geom name="train-microwave-1_g35" pos="-0.162565 0.068721 -0.136735" quat="1 0 0 0" type="mesh" rgba="0.5 0 0 1" mesh="train-microwave-1_original-38"/>
        <geom name="train-microwave-1_g34_visual" pos="-0.162565 0.068721 -0.136735" quat="1 0 0 0" type="mesh" contype="0" conaffinity="0" group="1" mass="0" mesh="train-microwave-1_original-20"/>
        <geom name="train-microwave-1_g35_visual" pos="-0.162565 0.068721 -0.136735" quat="1 0 0 0" type="mesh" contype="0" conaffinity="0" group="1" mass="0" mesh="train-microwave-1_original-38"/>
      </body>
      <body name="train-microwave-1_link_12" pos="-0.136735 -0.162565 -0.068721" quat="0.5 0.5 -0.5 -0.5">
        <inertial pos="-0.0270764 0.0834591 0.00146468" quat="0.424816 0.565551 -0.424962 0.56488" mass="0.0150911" diaginertia="5.3894e-06 2.76162e-06 2.75066e-06"/>
        <joint name="train-microwave-1_joint_12" pos="0 0 0" axis="0 0 -1" type="slide" limited="true" range="0 0.0012"/>
        <geom name="train-microwave-1_g36" pos="-0.162565 0.068721 -0.136735" quat="1 0 0 0" type="mesh" rgba="0.5 0 0 1" mesh="train-microwave-1_original-23"/>
        <geom name="train-microwave-1_g37" pos="-0.162565 0.068721 -0.136735" quat="1 0 0 0" type="mesh" rgba="0.5 0 0 1" mesh="train-microwave-1_original-37"/>
        <geom name="train-microwave-1_g36_visual" pos="-0.162565 0.068721 -0.136735" quat="1 0 0 0" type="mesh" contype="0" conaffinity="0" group="1" mass="0" mesh="train-microwave-1_original-23"/>
        <geom name="train-microwave-1_g37_visual" pos="-0.162565 0.068721 -0.136735" quat="1 0 0 0" type="mesh" contype="0" conaffinity="0" group="1" mass="0" mesh="train-microwave-1_original-37"/>
      </body>
      <body name="train-microwave-1_link_13" pos="-0.136735 -0.162565 -0.068721" quat="0.5 0.5 -0.5 -0.5">
        <inertial pos="0.0157634 0.103436 0.00145381" quat="1.15734e-06 0.707107 1.15734e-06 0.707107" mass="0.0149451" diaginertia="5.37555e-06 2.74744e-06 2.74693e-06"/>
        <joint name="train-microwave-1_joint_13" pos="0 0 0" axis="0 0 -1" type="slide" limited="true" range="0 0.0012"/>
        <geom name="train-microwave-1_g38" pos="-0.162565 0.068721 -0.136735" quat="1 0 0 0" type="mesh" rgba="0.5 0 0 1" mesh="train-microwave-1_original-48"/>
        <geom name="train-microwave-1_g39" pos="-0.162565 0.068721 -0.136735" quat="1 0 0 0" type="mesh" rgba="0.5 0 0 1" mesh="train-microwave-1_original-21"/>
        <geom name="train-microwave-1_g38_visual" pos="-0.162565 0.068721 -0.136735" quat="1 0 0 0" type="mesh" contype="0" conaffinity="0" group="1" mass="0" mesh="train-microwave-1_original-48"/>
        <geom name="train-microwave-1_g39_visual" pos="-0.162565 0.068721 -0.136735" quat="1 0 0 0" type="mesh" contype="0" conaffinity="0" group="1" mass="0" mesh="train-microwave-1_original-21"/>
      </body>
      <body name="train-microwave-1_link_14" pos="-0.136735 -0.162565 -0.068721" quat="0.5 0.5 -0.5 -0.5">
        <inertial pos="-0.00571194 0.103428 0.00148585" quat="-0.0488533 0.706881 0.0490433 0.703937" mass="0.0153893" diaginertia="5.4433e-06 2.79118e-06 2.78271e-06"/>
        <joint name="train-microwave-1_joint_14" pos="0 0 0" axis="0 0 -1" type="slide" limited="true" range="0 0.0012"/>
        <geom name="train-microwave-1_g40" pos="-0.162565 0.068721 -0.136735" quat="1 0 0 0" type="mesh" rgba="0.5 0 0 1" mesh="train-microwave-1_original-46"/>
        <geom name="train-microwave-1_g41" pos="-0.162565 0.068721 -0.136735" quat="1 0 0 0" type="mesh" rgba="0.5 0 0 1" mesh="train-microwave-1_original-27"/>
        <geom name="train-microwave-1_g40_visual" pos="-0.162565 0.068721 -0.136735" quat="1 0 0 0" type="mesh" contype="0" conaffinity="0" group="1" mass="0" mesh="train-microwave-1_original-46"/>
        <geom name="train-microwave-1_g41_visual" pos="-0.162565 0.068721 -0.136735" quat="1 0 0 0" type="mesh" contype="0" conaffinity="0" group="1" mass="0" mesh="train-microwave-1_original-27"/>
      </body>
      <body name="train-microwave-1_link_15" pos="-0.136735 -0.162565 -0.068721" quat="0.5 0.5 -0.5 -0.5">
        <inertial pos="-0.0270591 0.103509 0.00148112" quat="0.526718 0.471473 -0.529363 0.469101" mass="0.0153223" diaginertia="5.447e-06 2.81288e-06 2.76291e-06"/>
        <joint name="train-microwave-1_joint_15" pos="0 0 0" axis="0 0 -1" type="slide" limited="true" range="0 0.0012"/>
        <geom name="train-microwave-1_g42" pos="-0.162565 0.068721 -0.136735" quat="1 0 0 0" type="mesh" rgba="0.5 0 0 1" mesh="train-microwave-1_original-28"/>
        <geom name="train-microwave-1_g43" pos="-0.162565 0.068721 -0.136735" quat="1 0 0 0" type="mesh" rgba="0.5 0 0 1" mesh="train-microwave-1_original-45"/>
        <geom name="train-microwave-1_g42_visual" pos="-0.162565 0.068721 -0.136735" quat="1 0 0 0" type="mesh" contype="0" conaffinity="0" group="1" mass="0" mesh="train-microwave-1_original-28"/>
        <geom name="train-microwave-1_g43_visual" pos="-0.162565 0.068721 -0.136735" quat="1 0 0 0" type="mesh" contype="0" conaffinity="0" group="1" mass="0" mesh="train-microwave-1_original-45"/>
      </body>
      <body name="train-microwave-1_link_16" pos="-0.136735 -0.162565 -0.068721" quat="0.5 0.5 -0.5 -0.5">
        <inertial pos="0.0157643 0.123433 0.00146236" quat="0.521185 0.477846 -0.521504 0.47756" mass="0.0150669" diaginertia="5.38168e-06 2.7526e-06 2.75092e-06"/>
        <joint name="train-microwave-1_joint_16" pos="0 0 0" axis="0 0 -1" type="slide" limited="true" range="0 0.0012"/>
        <geom name="train-microwave-1_g44" pos="-0.162565 0.068721 -0.136735" quat="1 0 0 0" type="mesh" rgba="0.5 0 0 1" mesh="train-microwave-1_original-47"/>
        <geom name="train-microwave-1_g45" pos="-0.162565 0.068721 -0.136735" quat="1 0 0 0" type="mesh" rgba="0.5 0 0 1" mesh="train-microwave-1_original-25"/>
        <geom name="train-microwave-1_g44_visual" pos="-0.162565 0.068721 -0.136735" quat="1 0 0 0" type="mesh" contype="0" conaffinity="0" group="1" mass="0" mesh="train-microwave-1_original-47"/>
        <geom name="train-microwave-1_g45_visual" pos="-0.162565 0.068721 -0.136735" quat="1 0 0 0" type="mesh" contype="0" conaffinity="0" group="1" mass="0" mesh="train-microwave-1_original-25"/>
      </body>
      <body name="train-microwave-1_link_17" pos="-0.136735 -0.162565 -0.068721" quat="0.5 0.5 -0.5 -0.5">
        <inertial pos="-0.00561699 0.12342 0.00148575" quat="0.00340111 0.706275 -0.00319812 0.707922" mass="0.0154076" diaginertia="5.43481e-06 2.78378e-06 2.78115e-06"/>
        <joint name="train-microwave-1_joint_17" pos="0 0 0" axis="0 0 -1" type="slide" limited="true" range="0 0.0012"/>
        <geom name="train-microwave-1_g46" pos="-0.162565 0.068721 -0.136735" quat="1 0 0 0" type="mesh" rgba="0.5 0 0 1" mesh="train-microwave-1_original-44"/>
        <geom name="train-microwave-1_g47" pos="-0.162565 0.068721 -0.136735" quat="1 0 0 0" type="mesh" rgba="0.5 0 0 1" mesh="train-microwave-1_original-24"/>
        <geom name="train-microwave-1_g46_visual" pos="-0.162565 0.068721 -0.136735" quat="1 0 0 0" type="mesh" contype="0" conaffinity="0" group="1" mass="0" mesh="train-microwave-1_original-44"/>
        <geom name="train-microwave-1_g47_visual" pos="-0.162565 0.068721 -0.136735" quat="1 0 0 0" type="mesh" contype="0" conaffinity="0" group="1" mass="0" mesh="train-microwave-1_original-24"/>
      </body>
      <body name="train-microwave-1_link_18" pos="-0.136735 -0.162565 -0.068721" quat="0.5 0.5 -0.5 -0.5">
        <inertial pos="-0.0270962 0.123424 0.00148618" quat="-0.00870997 0.707735 0.00871353 0.706371" mass="0.0154121" diaginertia="5.43422e-06 2.78341e-06 2.78114e-06"/>
        <joint name="train-microwave-1_joint_18" pos="0 0 0" axis="0 0 -1" type="slide" limited="true" range="0 0.0012"/>
        <geom name="train-microwave-1_g48" pos="-0.162565 0.068721 -0.136735" quat="1 0 0 0" type="mesh" rgba="0.5 0 0 1" mesh="train-microwave-1_original-43"/>
        <geom name="train-microwave-1_g49" pos="-0.162565 0.068721 -0.136735" quat="1 0 0 0" type="mesh" rgba="0.5 0 0 1" mesh="train-microwave-1_original-26"/>
        <geom name="train-microwave-1_g48_visual" pos="-0.162565 0.068721 -0.136735" quat="1 0 0 0" type="mesh" contype="0" conaffinity="0" group="1" mass="0" mesh="train-microwave-1_original-43"/>
        <geom name="train-microwave-1_g49_visual" pos="-0.162565 0.068721 -0.136735" quat="1 0 0 0" type="mesh" contype="0" conaffinity="0" group="1" mass="0" mesh="train-microwave-1_original-26"/>
      </body>
      <body name="train-microwave-1_link_19" pos="0.0155518 0.0334461 0" quat="0.5 0.5 -0.5 -0.5">
        <inertial pos="-1.70874e-08 -0.0667362 -9.07341e-10" quat="0.707107 0 0 0.707107" mass="8.33956" diaginertia="0.417774 0.209422 0.209422"/>
        <joint name="train-microwave-1_joint_19" pos="0 0 0" axis="0 1 0"/>
        <geom name="train-microwave-1_g50" pos="0.0334461 0 0.0155519" quat="1 0 0 0" type="mesh" rgba="0.5 0 0 1" mesh="train-microwave-1_original-10"/>
        <geom name="train-microwave-1_g50_visual" pos="0.0334461 0 0.0155519" quat="1 0 0 0" type="mesh" contype="0" conaffinity="0" group="1" mass="0" mesh="train-microwave-1_original-10"/>
      </body>
    </body>
  </worldbody>

  <tendon>
    <fixed name="gripper0_finger2_12_cpl" limited="true" range="-1 1" stiffness="0.4" springlength="0.001">
      <joint joint="gripper0_finger_joint" coef="1"/>
      <joint joint="gripper0_left_inner_finger_joint" coef="-3"/>
      <joint joint="gripper0_left_inner_knuckle_joint" coef="1"/>
    </fixed>
    <fixed name="gripper0_finger1_12_cpl" limited="true" range="-1 1" stiffness="0.4" springlength="0.001">
      <joint joint="gripper0_right_outer_knuckle_joint" coef="1"/>
      <joint joint="gripper0_right_inner_finger_joint" coef="-3"/>
      <joint joint="gripper0_right_inner_knuckle_joint" coef="1"/>
    </fixed>
  </tendon>

  <actuator>
    <general name="robot0_torq_j1" joint="robot0_shoulder_pan_joint" ctrllimited="true" ctrlrange="-150 150"/>
    <general name="robot0_torq_j2" joint="robot0_shoulder_lift_joint" ctrllimited="true" ctrlrange="-150 150"/>
    <general name="robot0_torq_j3" joint="robot0_elbow_joint" ctrllimited="true" ctrlrange="-150 150"/>
    <general name="robot0_torq_j4" joint="robot0_wrist_1_joint" ctrllimited="true" ctrlrange="-28 28"/>
    <general name="robot0_torq_j5" joint="robot0_wrist_2_joint" ctrllimited="true" ctrlrange="-28 28"/>
    <general name="robot0_torq_j6" joint="robot0_wrist_3_joint" ctrllimited="true" ctrlrange="-28 28"/>
    <general name="gripper0_finger_1" joint="gripper0_finger_joint" ctrllimited="true" ctrlrange="0 0.8" biastype="affine" gainprm="20" biasprm="0 -20"/>
    <general name="gripper0_finger_2" joint="gripper0_right_outer_knuckle_joint" ctrllimited="true" ctrlrange="0 0.8" biastype="affine" gainprm="20" biasprm="0 -20"/>
  </actuator>

  <sensor>
    <force site="gripper0_ft_frame" name="gripper0_force_ee"/>
    <torque site="gripper0_ft_frame" name="gripper0_torque_ee"/>
  </sensor>
</mujoco>
